Workbook
Name List_Environment: Lists!$F$2:$F$6
Name List_Modules: Lists!$A$2:$A$10
Name List_Priority: Lists!$E$2:$E$5
Name List_Severity: Lists!$D$2:$D$5
Name List_Status: Lists!$C$2:$C$7
Name List_Testers: Lists!$B$2:$B$5

Sheet Main Dashboard
A1: SAHE SMS - QA Test Tracker
A2: School Administration & Higher Education SMS | Central QA Dashboard for Interns
A3: New to this file? Open the 'Guidelines' tab first (link below) for column definitions, status/severity rules and a worked example.
A4: -> Open Guidelines / How to Use
A6: QUICK JUMP - Select the sub-app you are testing
A7: Select sub-app: | B7: Analytics | D7: =HYPERLINK("#'"&B7&"'!A1","Go to selected sheet ->") -> Go to selected sheet ->
A9: # | B9: Sub-App / Module | C9: Open Sheet | D9: Assignee | E9: Total Cases | F9: Passed | G9: Failed | H9: Blocked | I9: Not Executed | J9: Pass Rate
A10: 1 | B10: Analytics | C10: Open -> | D10: Unassigned | E10: =COUNTA(Analytics!A5:A125) -> 69 | F10: =COUNTIF(Analytics!I5:I125,"Pass") -> 62 | G10: =COUNTIF(Analytics!I5:I125,"Fail") -> 6 | H10: =COUNTIF(Analytics!I5:I125,"Blocked") -> 1 | I10: =COUNTIF(Analytics!I5:I125,"Not Executed") -> 0 | J10: =IFERROR(F10/E10,0) -> 0.89855072 | K10: Completed
A11: 2 | B11: Academics | C11: Open -> | D11: Unassigned | E11: =COUNTA(Academics!A5:A300) -> 38 | F11: =COUNTIF(Academics!I5:I300,"Pass") -> 35 | G11: =COUNTIF(Academics!I5:I300,"Fail") -> 3 | H11: =COUNTIF(Academics!I5:I300,"Blocked") -> 0 | I11: =COUNTIF(Academics!I5:I300,"Not Executed") -> 0 | J11: =IFERROR(F11/E11,0) -> 0.92105263
A12: 3 | B12: Admissions | C12: Open -> | D12: Unassigned | E12: =COUNTA(Admissions!A5:A300) -> 3 | F12: =COUNTIF(Admissions!I5:I300,"Pass") -> 1 | G12: =COUNTIF(Admissions!I5:I300,"Fail") -> 2 | H12: =COUNTIF(Admissions!I5:I300,"Blocked") -> 0 | I12: =COUNTIF(Admissions!I5:I300,"Not Executed") -> 0 | J12: =IFERROR(F12/E12,0) -> 0.33333333
A13: 4 | B13: Students | C13: Open -> | D13: Unassigned | E13: =COUNTA(Students!A5:A253) -> 50 | F13: =COUNTIF(Students!I5:I253,"Pass") -> 38 | G13: =COUNTIF(Students!I5:I253,"Fail") -> 12 | H13: =COUNTIF(Students!I5:I253,"Blocked") -> 0 | I13: =COUNTIF(Students!I5:I253,"Not Executed") -> 0 | J13: =IFERROR(F13/E13,0) -> 0.76
A14: 5 | B14: Finance | C14: Open -> | D14: Unassigned | E14: =COUNTA(Finance!#REF!) -> 1 | F14: =COUNTIF(Finance!#REF!,"Pass") -> #REF! | G14: =COUNTIF(Finance!#REF!,"Fail") -> #REF! | H14: =COUNTIF(Finance!#REF!,"Blocked") -> #REF! | I14: =COUNTIF(Finance!#REF!,"Not Executed") -> #REF! | J14: =IFERROR(F14/E14,0) -> 0
A15: 6 | B15: Human Resources | C15: Open -> | D15: Unassigned | E15: =COUNTA('Human Resources'!A5:A300) -> 60 | F15: =COUNTIF('Human Resources'!I5:I300,"Pass") -> 57 | G15: =COUNTIF('Human Resources'!I5:I300,"Fail") -> 3 | H15: =COUNTIF('Human Resources'!I5:I300,"Blocked") -> 0 | I15: =COUNTIF('Human Resources'!I5:I300,"Not Executed") -> 0 | J15: =IFERROR(F15/E15,0) -> 0.95
A16: 7 | B16: Agents | C16: Open -> | D16: Unassigned | G16: =COUNTIF(Analytics!I11:I131,"Fail") -> 4 | J16: =IFERROR(F16/E16,0) -> 0
A17: 8 | B17: Compliance and Audit | C17: Open -> | D17: Unassigned | E17: =COUNTA('Compliance and Audit'!A5:A300) -> 1 | F17: =COUNTIF('Compliance and Audit'!I5:I300,"Pass") -> 0 | G17: =COUNTIF('Compliance and Audit'!I5:I300,"Fail") -> 0 | H17: =COUNTIF('Compliance and Audit'!I5:I300,"Blocked") -> 0 | I17: =COUNTIF('Compliance and Audit'!I5:I300,"Not Executed") -> 0 | J17: =IFERROR(F17/E17,0) -> 0
A18: 9 | B18: Settings | C18: Open -> | D18: Unassigned | E18: =COUNTA(Settings!A5:A300) -> 0 | F18: =COUNTIF(Settings!I5:I300,"Pass") -> 0 | G18: =COUNTIF(Settings!I5:I300,"Fail") -> 0 | H18: =COUNTIF(Settings!I5:I300,"Blocked") -> 0 | I18: =COUNTIF(Settings!I5:I300,"Not Executed") -> 0 | J18: =IFERROR(F18/E18,0) -> 0
B19: TOTAL | E19: =SUM(E10:E18) -> 222 | F19: =SUM(F10:F18) -> #REF! | G19: =SUM(G10:G18) -> #REF! | H19: =SUM(H10:H18) -> #REF! | I19: =SUM(I10:I18) -> #REF! | J19: =IFERROR(F19/E19,0) -> 0
A21: Note: New sub-apps/modules may be added over time. To add one: duplicate any module sheet, rename the tab, add the new name to the 'Modules' list on the hidden 'Lists' sheet, then copy a summary row above and update the sheet references.

Sheet Guidelines
A1: SAHE SMS - QA Testing Guidelines & How to Use This Workbook
A2: Read this sheet before you start testing. It explains the workbook layout, every column, and the rules for statuses, severity and priority.
A4: << Back to Dashboard
A6: 1. Workbook Structure
A7: - Main Dashboard - overview of every sub-app with live pass/fail counts and a quick-jump selector.
A8: - Guidelines (this sheet) - instructions, definitions and a worked example.
A9: - One sheet per sub-app - Analytics, Academics, Admissions, Students, Finance, Human Resources, Agents, Compliance and Audit, Settings. Each developer tests inside the sheet(s) assigned to them.
A10: - New sub-apps can be added later - see the note at the bottom of the Main Dashboard.
A12: 2. Getting Started (for interns)
A13: - 1. Open 'Main Dashboard' and check the 'Assigned Intern' column, or ask your lead which sub-app you own.
A14: - 2. Use the 'Select sub-app' dropdown on the Dashboard, or click 'Open ->' next to your module, to jump straight to your sheet.
A15: - 3. Row 4 on every module sheet is a filled-in SAMPLE row (shaded gold) - use it as a reference for formatting, then start entering your own test cases from row 5 onward.
... A21: 3. Column Definitions
A22: Column | B22: Meaning | E22: Example / Notes
A23: Test Case ID | B23: Unique ID per test case | E23: AN-001, AC-014 (module prefix + running number)
A24: Feature / Sub-Module | B24: Screen or feature under test | E24: e.g. Enrollment Trends Widget, Fee Invoice PDF
A25: Test Scenario | B25: One-line summary of what is being verified | E25: Verify enrollment chart loads correctly
A26: Test Steps | B26: Numbered steps to reproduce the test | E26: 1. Login 2. Navigate 3. Action 4. Observe
A27: Preconditions | B27: State required before the test can run | E27: User has Admin role; sample data exists
A28: Test Data | B28: Specific input values used | E28: Date range = Last 12 Months
A29: Expected Result | B29: What SHOULD happen if the feature works | E29: Chart loads in <3s with correct totals
A30: Actual Result | B30: What ACTUALLY happened when you tested | E30: Chart loaded in 2s, totals matched
A31: Status | B31: Current test outcome (dropdown) | E31: Not Executed / In Progress / Pass / Fail / Blocked / Retest
A32: Severity | B32: How serious the impact of the bug is (dropdown) | E32: Critical / High / Medium / Low
A33: Priority | B33: How urgently it should be fixed (dropdown) | E33: P1-Critical / P2-High / P3-Medium / P4-Low
... A38: Comments / Remarks | B38: Any extra context | E38: Retested after fix on build 1.4.2
A40: 4. Status Definitions & Color Coding
B41: Not Executed | C41: Test case written but not run yet (default state).
B42: In Progress | C42: Testing has started but is not finished.
B43: Pass | C43: Actual result matches the expected result.
B44: Fail | C44: Actual result does not match the expected result - log a bug.
B45: Blocked | C45: Cannot be tested (e.g. environment down, dependency missing).
B46: Retest | C46: A previously failed case is being re-verified after a fix.
A48: 5. Severity vs. Priority - What's the Difference?
A49: Severity = how BAD the bug is technically (impact on the system). Priority = how SOON it needs fixing (business urgency). A cosmetic typo on the homepage can be Low severity but High priority if leadership is demoing the app tomorrow.
A50: Critical | C50: System crash, data loss, security breach, module completely unusable.
A51: High | C51: Major feature broken, no workaround available.
A52: Medium | C52: Feature partly broken, workaround exists.
A53: Low | C53: Cosmetic issue, typo, minor UI misalignment.
A55: 6. Worked Example
...

Sheet Lists
A1: Modules | B1: Testers | C1: Status | D1: Severity | E1: Priority | F1: Environment
A2: Analytics | B2: Intern 1 | C2: Not Executed | D2: Critical | E2: P1 - Critical | F2: Dev
A3: Academics | B3: Intern 2 | C3: In Progress | D3: High | E3: P2 - High | F3: QA
A4: Admissions | B4: Intern 3 | C4: Pass | D4: Medium | E4: P3 - Medium | F4: Staging
A5: Students | B5: Unassigned | C5: Fail | D5: Low | E5: P4 - Low | F5: UAT
A6: Finance | C6: Blocked | F6: Production
A7: Human Resources | C7: Retest
A8: Agents
A9: Compliance and Audit
A10: Settings

Sheet Analytics
A1: SAHE SMS | Analytics - QA Test Cases
A2: << Back to Dashboard
A3: Test Case ID | B3: Feature / Sub-Module | C3: Test Scenario | D3: Test Steps | E3: Preconditions | F3: Test Data | G3: Expected Result | H3: Actual Result | I3: Status | J3: Severity | K3: Priority | L3: Tested By | M3: Date Tested | N3: Environment | O3: Bug ID / Link | P3: Comments / Remarks
A4: AN-001 | B4: Enrollment Trends Widget | C4: Verify enrollment trend chart loads on Analytics dashboard | D4: 1. Log in as Admin 2. Navigate to Analytics > Dashboard 3. Observe 'Enrollment Trends' widget 4. Change date range filter to 'Last 12 Months' | E4: User has Admin role; at least 1 academic year of data exists | F4: Date range: Last 12 Months | G4: Chart renders within 3 seconds and reflects selected date range with correct totals | H4: Chart rendered in 2s; totals matched source data | I4: Pass | J4: Medium | K4: P2 - High | L4: Intern 1 | M4: 2026-08-01 | N4: QA | O4: - | P4: Sample row for reference only - overwrite or delete before real testing
A5: ANA-ADM-001 | B5: Admin Access & Session | C5: Signed-out visitor opens Tickets Analytics directly | D5: 1. Sign out or use a private browser window. 2. Open https://staging.sahe-sms.neuronnest.com/analytics/tickets/. 3. Observe the redirect and page content. 4. Confirm no Analytics values flash before sign-in. | E5: No authenticated session exists. | F5: https://staging.sahe-sms.neuronnest.com/analytics/tickets/ | G5: The user is redirected to the SAHE SMS sign-in page; no dashboard KPI, chart, ticket, requester or email data is exposed. | H5: When accessing /analytics/tickets/ while logged out in an Incognito window, the application did not redirect to the Sign In page. A Django "Page not found (404)" debug page was displayed instead. | I5: Fail | J5: Critical | K5: P0 - Critical | L5: Surakshya k.C. | M5: 46246 | N5: QA | P5: Unauthenticated access did not redirect to Sign In. Django 404 debug page was exposed with DEBUG=True.
A6: ANA-ADM-002 | B6: Admin Access & Session | C6: Signed-out visitor opens Forms Analytics directly | D6: 1. Sign out or use a private browser window. 2. Open https://staging.sahe-sms.neuronnest.com/analytics/forms/. 3. Observe the redirect and page content. 4. Confirm no Analytics values flash before sign-in. | E6: No authenticated session exists. | F6: https://staging.sahe-sms.neuronnest.com/analytics/forms/ | G6: The user is redirected to sign-in; no form counts, queue details or chart data is exposed. | H6: When accessing /analytics/forms/ while logged out in an Incognito window, the application did not redirect to the Sign In page. A Django "Page not found (404)" debug page was displayed instead. | I6: Fail | J6: Critical | K6: P0 - Critical | L6: Surakshya k.C. | M6: 46246 | N6: QA | P6: Unauthenticated access did not redirect to Sign In. Django 404 debug page was exposed with DEBUG=True.
A7: ANA-ADM-003 | B7: Admin Access & Session | C7: Admin reaches Tickets Analytics after successful sign-in | D7: 1. Open https://staging.sahe-sms.neuronnest.com/analytics/tickets/ while signed out. 2. Sign in through the normal sign-in page with an authorised Admin account. 3. Complete any required authentication flow. 4. Observe the landing page and URL. | E7: Admin/Superuser account is authenticated on the SAHE SMS staging environment unless the case states otherwise. | F7: Authorised Admin/Superuser test account; Tickets Analytics direct URL. | G7: Sign-in succeeds and the authorised Admin reaches Tickets Analytics without a redirect loop, error page or blank screen. | H7: Sign-in succeeded and the authorized Superuser successfully accessed Tickets Analytics. The page loaded correctly with ticket KPI data and no redirect loop, blank screen, or error page. | I7: Pass | J7: High | K7: P1 - High | L7: Surakshya k.C. | M7: 46246 | N7: QA | P7: Ticket Analytics successfully accessible through Analytics > Ticketsafter authorized sign-in.
A8: ANA-ADM-004 | B8: Admin Access & Session | C8: Admin reaches Forms Analytics after successful sign-in | D8: 1. Open https://staging.sahe-sms.neuronnest.com/analytics/forms/ while signed out. 2. Sign in through the normal sign-in page with an authorised Admin account. 3. Complete any required authentication flow. 4. Observe the landing page and URL. | E8: Admin/Superuser account is authenticated on the SAHE SMS staging environment unless the case states otherwise. | F8: Authorised Admin/Superuser test account; Forms Analytics direct URL. | G8: Sign-in succeeds and the authorised Admin reaches Forms Analytics without a redirect loop, error page or blank screen. | H8: Authorized Superuser successfully accessed Forms Analytics through the application navigation. The page loaded correctly without any error, redirect loop, or blank screen. | I8: Pass | J8: High | K8: P1 - High | L8: Surakshya k.C. | M8: 46246 | N8: QA | P8: Forms Analytics successfully accessible through Analytics > Forms after authorized sign-in.
A9: ANA-ADM-005 | B9: Admin Access & Session | C9: Refresh preserves the Admin Analytics session | D9: 1. Sign in with a clean Admin/Superuser session. 2. Open Tickets Analytics. 3. Wait for the page and charts to finish loading. 4. Press browser Refresh three times, including once after scrolling to the Recent Tickets section; record the result. | E9: Admin/Superuser account is authenticated on the SAHE SMS staging environment unless the case states otherwise. | F9: Use controlled staging data only; do not use production or real personal data. | G9: Every refresh returns the same authorised page, keeps the Admin signed in and does not duplicate charts, loaders or page sections. | H9: Tickets Analytics was refreshed three times while logged in as Superuser. The page reloaded successfully each time, the authenticated session was preserved, and no errors, duplicate content, blank page, or stuck loading indicators were observed | I9: Pass | J9: High | K9: P1 - High | L9: Surakshya k.C. | M9: 46246 | N9: QA | P9: Analytics session remained active and Tickets Analytics loaded normally after repeated browser refreshes.
A10: ANA-ADM-006 | B10: Admin Access & Session | C10: Browser Back and Forward preserve correct Analytics state | D10: 1. Open Tickets Analytics. 2. Navigate to Forms Analytics. 3. Use browser Back, then Forward. 4. Check URL, active sidebar item, title, content and chart rendering after each action. | E10: Admin/Superuser account is authenticated on the SAHE SMS staging environment unless the case states otherwise. | F10: Use controlled staging data only; do not use production or real personal data. | G10: Back returns to Tickets and Forward returns to Forms; page title, active navigation and content always match the current URL. | H10: Browser Back navigation returned from Forms Analytics to Tickets Analytics correctly, and Forward navigation returned to Forms Analytics. The URL, selected sidebar item, page title, and page content matched the expected page in both directions. | I10: Pass | J10: Medium | K10: P2 - Medium | L10: Surakshya k.C. | M10: 46246 | N10: QA | P10: Browser Back and Forward navigation worked correctly between Tickets Analytics and Forms Analytics.
A11: ANA-ADM-007 | B11: Admin Access & Session | C11: Admin signs out from an Analytics page | D11: 1. Open Tickets Analytics as Admin. 2. Use the visible Sign Out action. 3. Confirm sign-out if the UI asks. 4. Attempt to reopen both Analytics URLs. | E11: Admin/Superuser account is authenticated on the SAHE SMS staging environment unless the case states otherwise. | F11: Use controlled staging data only; do not use production or real personal data. | G11: The session ends, sign-in is shown, and both Analytics URLs remain protected. | H11: After signing out from Analytics, the authenticated session ended successfully and the Sign In page was displayed. Analytics pages were not accessible while logged out. | I11: Pass | J11: Critical | K11: P0 - Critical | L11: Surakshya k.C. | M11: 46247 | N11: QA | P11: Sign out worked correctly. User was returned to the Sign In page and authenticated Analytics access was no longer available.
A12: ANA-ADM-008 | B12: Admin Access & Session | C12: Browser Back after sign-out does not reveal cached Analytics data | D12: 1. Open Forms Analytics as Admin. 2. Sign out. 3. Press browser Back. 4. Inspect visible content and refresh the page. | E12: Admin/Superuser account is authenticated on the SAHE SMS staging environment unless the case states otherwise. | F12: Use controlled staging data only; do not use production or real personal data. | G12: Protected Analytics data is not usable or exposed from browser cache; the user remains signed out and is returned to sign-in when necessary. | H12: After signing out and reaching the Sign In page, clicking the browser Back button displayed the previously visited Forms Analytics page with analytics data still visible. The View Queue links remained clickable and opened queue content, while other navigation such as Tickets did not open. | I12: Fail | J12: Critical | K12: P0 - Critical | L12: Surakshya k.C. | M12: 46247 | N12: QA | P12: Post-logout browser Back navigation exposes previously loaded Forms Analytics data. View Queue links also remain interactive/open after logout. Other protected navigation such as Tickets does not open.
A13: ANA-ADM-009 | B13: Admin Access & Session | C13: Expired session is handled safely | D13: 1. Open Tickets Analytics as Admin. 2. Allow the session to expire using the approved staging method. 3. Refresh the page and click Forms in the sidebar. 4. Observe redirect, message and data visibility. | E13: Admin/Superuser account is authenticated on the SAHE SMS staging environment unless the case states otherwise. | F13: Approved short-session test configuration or expired test session. | G13: The user is redirected to sign-in with a clear outcome; no partial Analytics data, stack trace or server error is displayed. | H13: Test could not be executed because the approved method or timeout duration for expiring an authenticated staging session has not been provided. | I13: Blocked | J13: Critical | K13: P0 - Critical | L13: Surakshya k.C. | M13: 46247 | N13: QA | P13: Blocked pending confirmation from the development/team lead regarding the approved staging session-expiry method or configured session timeout.
A14: ANA-ADM-010 | B14: Admin Access & Session | C14: Analytics session remains consistent across two browser tabs | D14: 1. Open Tickets Analytics in tab A. 2. Open Forms Analytics in tab B. 3. Refresh and switch between both tabs. 4. Sign out in tab B and re-check tab A. | E14: Admin/Superuser account is authenticated on the SAHE SMS staging environment unless the case states otherwise. | F14: Use controlled staging data only; do not use production or real personal data. | G14: Both tabs show the correct page while authenticated; after sign-out, protected actions in the other tab require authentication and do not reveal stale data. | H14: Tickets Analytics and Forms Analytics were opened in separate browser tabs under the same authenticated session. After signing out from the Forms tab, the previously loaded Tickets Analytics page remained visually displayed until refreshed. On refresh, it redirected to the Sign In page and authenticated access was no longer available. | I14: Pass | J14: High | K14: P1 - High | L14: Surakshya k.C. | M14: 46247 | N14: QA | P14: Logout was applied across browser tabs. Previously rendered Tickets content remained visible until refresh, but refreshing correctly required authentication.
A15: ANA-ADM-011 | B15: Admin Access & Session | C15: Unknown Analytics child URL returns a safe not-found response | D15: 1. Sign in as Admin. 2. Open https://staging.sahe-sms.neuronnest.com/analytics/not-a-real-page/. 3. Observe the page, status and navigation. 4. Return to Analytics using visible navigation. | E15: Admin/Superuser account is authenticated on the SAHE SMS staging environment unless the case states otherwise. | F15: https://staging.sahe-sms.neuronnest.com/analytics/not-a-real-page/ | G15: A branded 404/not-found response appears without sensitive details; the user can navigate back safely. | H15: When an invalid Analytics URL was accessed while authenticated, the application displayed the Django debug 404 page instead of a safe user-friendly 404 page. Internal URL patterns and DEBUG=True information were exposed. | I15: Fail | J15: Medium | K15: P2 - Medium | L15: Surakshya k.C. | M15: 46247 | N15: QA | P15: Invalid URL exposes Django debug information, including internal URL configuration/routes and DEBUG=True.
A16: ANA-ADM-012 | B16: Analytics Navigation | C16: Admin sidebar displays the Analytics section | D16: 1. Sign in with a clean Admin/Superuser session. 2. Open the main SAHE SMS dashboard. 3. Wait for the page and charts to finish loading. 4. Inspect the full sidebar and locate Analytics. | E16: Admin/Superuser account is authenticated on the SAHE SMS staging environment unless the case states otherwise. | F16: Use controlled staging data only; do not use production or real personal data. | G16: Analytics is visible to the Admin with the chart icon and contains Tickets and Forms child items. | H16: The Analytics section was displayed correctly in the Admin sidebar. Both Tickets and Forms menu items were visible under Analytics and available to the authorized Superuser. | I16: Pass | J16: High | K16: P1 - High | L16: Surakshya k.C. | M16: 46247 | N16: QA | P16: Analytics section is visible in the Admin sidebar with both Tickets and Forms child menu items.
... A73: ANA-ADM-069 | B73: Security & Read-only | C73: Admin Analytics actions use HTTPS | D73: 1. Sign in with the Admin test account. 2. Inspect the current page and all internal Analytics navigation destinations. 3. Observe URL, visible output and browser security/console state. 4. Record evidence without entering real personal data. | E73: Admin/Superuser account is authenticated on the SAHE SMS staging environment unless the case states otherwise. | F73: Use controlled staging data only; do not use production or real personal data. | G73: All SAHE SMS Analytics requests remain on HTTPS with no mixed-content security warning affecting page behaviour. | H73: Analytics pages, internal Analytics navigation and external platform links were verified to use secure HTTPS connections. No insecure HTTP navigation or browser security warnings were observed. | I73: Pass | J73: Critical | K73: P0 - Critical | L73: Surakshya k.C. | M73: 46248 | N73: QA | P73: Tickets Analytics, Forms Analytics and external platform navigation operated over secure HTTPS connections as expected.

Sheet Academics
A1: SAHE SMS | Academics - QA Test Cases
A2: << Back to Dashboard
A3: Test Case ID | B3: Feature / Sub-Module | C3: Test Scenario | D3: Test Steps | E3: Preconditions | F3: Test Data | G3: Expected Result | H3: Actual Result | I3: Status | J3: Severity | K3: Priority | L3: Tested By | M3: Date Tested | N3: Environment | O3: Bug ID / Link | P3: Comments / Remarks
A4: AN-001 | B4: Enrollment Trends Widget | C4: Verify enrollment trend chart loads on Analytics dashboard | D4: 1. Log in as Admin 2. Navigate to Analytics > Dashboard 3. Observe 'Enrollment Trends' widget 4. Change date range filter to 'Last 12 Months' | E4: User has Admin role; at least 1 academic year of data exists | F4: Date range: Last 12 Months | G4: Chart renders within 3 seconds and reflects selected date range with correct totals | H4: Chart rendered in 2s; totals matched source data | I4: Pass | J4: Medium | K4: P2 - High | L4: Intern 1 | M4: 2026-08-01 | N4: QA | O4: - | P4: Sample row for reference only - overwrite or delete before real testing
A5: ACA-ADM-001 | B5: Courses | C5: Verify add Courses | D5: 1. Log in as Admin 2. Navigate to Academics > Courses 3. Add Courses | E5: User has admin role. | F5: https://staging.sahe-sms.neuronnest.com/academics/new/ | G5: Populate required input fields ([Field Name]) with valid/invalid test data | H5: Populate required input fields ([Field Name]) with valid/invalid test data | I5: Pass | J5: Low | K5: P4 - Low | L5: Dibesh | M5: 46246 | N5: QA
A6: ACA-ADM-002 | B6: Courses | C6: Verify Accuracy of Search bar | D6: 1. Log in as Admin 2. Navigate to Academics > Courses 3. Search Bar | E6: User has admin role | F6: https://staging.sahe-sms.neuronnest.com/academics/ | G6: Show what is being searched | H6: Showed what is being searched | I6: Pass | J6: Low | K6: P4 - Low | L6: Dibesh | M6: 46246 | N6: QA
A7: ACA-ADM-003 | B7: Courses | C7: Verify Reset on search bar | D7: 1. Log in as Admin 2. Navigate to Academics > Courses 3. Search Bar 4.reset | E7: User has admin role | F7: https://staging.sahe-sms.neuronnest.com/academics/ | G7: Reset what was searched | H7: Reset what was searched | I7: Pass | J7: Low | K7: P4 - Low | L7: Dibesh | M7: 46246 | N7: QA
A8: ACA-ADM-004 | B8: Subjects | C8: Verify add Subject | D8: 1. Log in as Admin 2. Navigate to Academics > Subjects 3. Add Courses | E8: User has admin role | F8: https://staging.sahe-sms.neuronnest.com/academics/subjects/new/ | G8: Populate required input fields ([Field Name]) with valid/invalid test data | H8: Populate required input fields ([Field Name]) with valid/invalid test data | I8: Pass | J8: Low | K8: P4 - Low | L8: Dibesh | M8: 46248 | N8: QA
A9: ACA-ADM-005 | B9: Subjects | C9: Verify Accuracy of Search bar | D9: 1. Log in as Admin 2. Navigate to Academics >Subjects 3. Search Bar | E9: User has admin role | F9: https://staging.sahe-sms.neuronnest.com/academics/subjects/ | G9: Show what is being searched | H9: Showed what is being searched | I9: Pass | J9: Low | K9: P4 - Low | L9: Dibesh | M9: 46248 | N9: QA
A10: ACA-ADM-006 | B10: Subjects | C10: Verify Reset on search bar | D10: 1. Log in as Admin 2. Navigate to Academics > Subjects 3. Search Bar 4.reset | E10: User has admin role | F10: https://staging.sahe-sms.neuronnest.com/academics/subjects/ | G10: Reset what was searched | H10: Reset what was searched | I10: Pass | J10: Low | K10: P4 - Low | L10: Dibesh | M10: 46248 | N10: QA
A11: ACA-ADM-007 | B11: Subjects | C11: View Subject Details accuracy | D11: 1. Log in as Admin 2. Navigate to a Academics> Subject > view 3.Subject Details | E11: User has admin role | F11: https://staging.sahe-sms.neuronnest.com/academics/subjects/2/ | G11: View individual Subject | H11: View Individial Subject | I11: Pass | J11: Low | K11: P4 - Low | L11: Dibesh | M11: 46248 | N11: QA
A12: ACA-ADM-008 | B12: Subjects | C12: Edit individial Subject | D12: 1. Log in as Admin 2. Navigate to Academics > Subject > Individial Subject 3. Edit Subject | E12: User has admin role | F12: https://staging.sahe-sms.neuronnest.com/academics/subjects/2/edit/ | G12: Edit Individual Subject | H12: edit individial subject | I12: Pass | J12: Low | K12: P4 - Low | L12: Dibesh | M12: 46248 | N12: QA
A13: ACA-ADM-009 | B13: Subjects | C13: Back to Subject List | D13: 1. Log in as Admin 2. Navigate to Academics > Subject > Individial Subject 3. Back to List | E13: User has admin role | F13: https://staging.sahe-sms.neuronnest.com/academics/subjects/ | G13: Back to Subject List | H13: Back to Subject List | I13: Pass | J13: Low | K13: P4 - Low | L13: Dibesh | M13: 46248 | N13: QA
A14: ACA-ADM-010 | B14: Subjects | C14: Removing a Subject | D14: 1. Log in as Admin 2. Navigate to Academics>Subject 3. Delete an individual Subject | E14: User has admin role | F14: https://staging.sahe-sms.neuronnest.com/academics/subjects/63/delete/ | G14: Remove the selected Subject | H14: Removed the deleted Subject | I14: Pass | J14: Low | K14: P4 - Low | L14: Dibesh | M14: 46248 | N14: QA
A15: ACA-ADM-011 | B15: Subjects | C15: Statistical Value no display | D15: 1. Log in as Admin 2. Navigate to Academics > Subject 3. Manage academic subjects and units. | E15: User has admin role | F15: https://staging.sahe-sms.neuronnest.com/academics/subjects/ | G15: Core Subject Number | H15: Result showing 0 | I15: Fail | J15: Medium | K15: P3 - Medium | L15: Dibesh | M15: 46248 | N15: QA
A16: ACA-ADM-012 | B16: Prerequisite | C16: Add Prerequisites | D16: 1. Log in as Admin 2. Navigate to Academics>Prerequisites 3. Add Prerequisites | E16: User has admin role | F16: https://staging.sahe-sms.neuronnest.com/academics/requisites/new/ | G16: Populate required input fields ([Field Name]) with valid/invalid test data | H16: Populate required input fields ([Field Name]) with valid/invalid test data | I16: Pass | J16: Low | K16: P4 - Low | L16: Dibesh | M16: 46248 | N16: QA
... A42: ACA-ADM-038 | B42: Cost Analysis | C42: Verify Expand and Collapse | D42: 1.Log in as Admin 2. Navigate to Academics>Cost Analysis 3.Expand all 4..Collapse all | E42: User has admin role | F42: https://staging.sahe-sms.neuronnest.com/academics/cost-analysis/ | G42: Expand and Collapse Cost Analysis | H42: Expanded and callapsed cost analysis | I42: Pass | J42: Low | K42: P4 - Low | L42: Dibesh | M42: 46255 | N42: QA

Sheet Admissions
A1: SAHE SMS | Admissions - QA Test Cases
A2: << Back to Dashboard
A3: Test Case ID | B3: Feature / Sub-Module | C3: Test Scenario | D3: Test Steps | E3: Preconditions | F3: Test Data | G3: Expected Result | H3: Actual Result | I3: Status | J3: Severity | K3: Priority | L3: Tested By | M3: Date Tested | N3: Environment | O3: Bug ID / Link | P3: Comments / Remarks
A4: AN-001 | B4: Enrollment Trends Widget | C4: Verify enrollment trend chart loads on Analytics dashboard | D4: 1. Log in as Admin 2. Navigate to Analytics > Dashboard 3. Observe 'Enrollment Trends' widget 4. Change date range filter to 'Last 12 Months' | E4: User has Admin role; at least 1 academic year of data exists | F4: Date range: Last 12 Months | G4: Chart renders within 3 seconds and reflects selected date range with correct totals | H4: Chart rendered in 2s; totals matched source data | I4: Pass | J4: Medium | K4: P2 - High | L4: Intern 1 | M4: 2026-08-01 | N4: QA | O4: - | P4: Sample row for reference only - overwrite or delete before real testing
A5: ADM-ADM-001 | B5: Overview | C5: Total Applications Details accuracy | D5: 1. Log in as Admin 2. Navigate to Admissions> Overview 3. Navigate to Total applications | E5: User has Admin role | F5: https://staging.sahe-sms.neuronnest.com/admissions/applications/ | G5: Details of applications | H5: Details of application | I5: Pass | J5: Low | K5: P4 - Low | L5: Dibesh | M5: 46251 | N5: QA
A6: ADM-ADM-002 | B6: Overview | C6: New application | D6: 1.log in as admin 2. Navigate to Admissions>Overview 3. New application 4. Fill out details with * | E6: User has admin role | F6: https://staging.sahe-sms.neuronnest.com/admissions/apply/ | G6: Populate required input fields ([Field Name]) with valid/invalid test data | H6: Error page | I6: Fail | J6: High | K6: P2 - High | L6: Dibesh | M6: 46251 | N6: OA
A7: ADM-ADM-003 | B7: Overview | C7: New application | D7: 1. Log in as Admin. 2. Navigate to Admissions → Overview. 3. Click New Application. 4. Complete all required fields with valid dummy data. 5. Select direct application/not applying through an Agent. 6. Review and submit the application. | E7: Admin is logged in; active course and intake exist; Admissions application form is available. | G7: Application should submit successfully, create one application with Submitted status and display a confirmation page with the application reference number. | H7: Submission failed. The website displayed a Django debug page with IntegrityError: null value in column "applied_via_agent" violates not-null constraint. No success confirmation page was displayed. | I7: Fail | K7: P0 – Critical | L7: Saugat KC | M7: 46252 | N7: Staging | O7: ADM-BUG-001

Sheet Students
A1: SAHE SMS | Students - QA Test Cases
A2: << Back to Dashboard
A3: Test Case ID | B3: Feature / Sub-Module | C3: Test Scenario | D3: Test Steps | E3: Preconditions | F3: Test Data | G3: Expected Result | H3: Actual Result | I3: Status | J3: Severity | K3: Priority | L3: Tested By | M3: Date Tested | N3: Environment | O3: Bug ID / Link | P3: Comments / Remarks
A4: AN-001 | B4: Enrollment Trends Widget | C4: Verify enrollment trend chart loads on Analytics dashboard | D4: 1. Log in as Admin 2. Navigate to Analytics > Dashboard 3. Observe 'Enrollment Trends' widget 4. Change date range filter to 'Last 12 Months' | E4: User has Admin role; at least 1 academic year of data exists | F4: Date range: Last 12 Months | G4: Chart renders within 3 seconds and reflects selected date range with correct totals | H4: Chart rendered in 2s; totals matched source data | I4: Pass | J4: Medium | K4: P2 - High | L4: Intern 1 | M4: 2026-08-01 | N4: QA | O4: - | P4: Sample row for reference only - overwrite or delete before real testing
A5: STU-ADM-001 | B5: UX, Accessibility & Reliability | C5: Keyboard navigation | D5: 1. Sign in at https://staging.sahe-sms.neuronnest.com/ with a clean Admin/Superuser control account. 2. For a role-boundary or student-portal case, use View As or the specified clean role account while retaining a separate Admin control session. 3. Follow the source procedure: • Use the appropriate authorised role for each page. • Review representative dashboard, list, form, modal and portal pages. • Traverse sidebar, filters, tables, modals and forms using keyboard only. • Record the displayed values, response and audit/notification result. 4. Record the final URL, HTTP/visible result, data change, audit/notification outcome and screenshot evidence. | E5: Admin/Superuser staging access is available. Use synthetic records only. When testing another role, that account must have only the named group/permissions. Representative populated and empty datasets are available. Role under test must have no unrelated groups or direct permissions. | F5: Desktop/mobile viewports, keyboard-only, 200% zoom and screen reader. | G5: Visible focus, logical order, no traps, all actions operable. | H5: PASS — Executed in the signed-in Admin/Superuser staging session. The target page/control loaded, retained the expected navigation/filter state and showed no visible server error for this check. Evidence recorded from the live DOM and final URL on 2026-08-15. | I5: Pass | J5: Medium | K5: P2 - Medium | L5: Saugat KC | M5: 46249 | N5: Staging
A6: STU-ADM-002 | B6: UX, Accessibility & Reliability | C6: Error pages | D6: 1. Sign in at https://staging.sahe-sms.neuronnest.com/ with a clean Admin/Superuser control account. 2. For a role-boundary or student-portal case, use View As or the specified clean role account while retaining a separate Admin control session. 3. Follow the source procedure: • Use the appropriate authorised role for each page. • Review representative dashboard, list, form, modal and portal pages. • Trigger 403, 404 and a controlled validation failure. • Record the displayed values, response and audit/notification result. 4. Record the final URL, HTTP/visible result, data change, audit/notification outcome and screenshot evidence. | E6: Admin/Superuser staging access is available. Use synthetic records only. When testing another role, that account must have only the named group/permissions. Representative populated and empty datasets are available. Role under test must have no unrelated groups or direct permissions. | F6: Desktop/mobile viewports, keyboard-only, 200% zoom and screen reader. | G6: Branded safe page/message; no debug trace or sensitive settings. | H6: FAIL — Invalid Student profile and transcript URLs displayed Django's detailed DEBUG 404 page with URL patterns, internal view names and explicit DEBUG=True disclosure. | I6: Fail | J6: Medium | K6: P2 - Medium | L6: Saugat KC | M6: 46249 | N6: Staging | O6: BUG-STU-WEB-001
A7: STU-ADM-003 | B7: Dashboard | C7: Dashboard loads for authorised staff | D7: 1. Sign in at https://staging.sahe-sms.neuronnest.com/ with a clean Admin/Superuser control account. 2. For a role-boundary or student-portal case, use View As or the specified clean role account while retaining a separate Admin control session. 3. Follow the source procedure: • Sign in as a staff user with students.view_student. • Open Students > Services (/students/). • Load the page and refresh once. • Record the displayed values, response and audit/notification result. 4. Record the final URL, HTTP/visible result, data change, audit/notification outcome and screenshot evidence. | E7: Admin/Superuser staging access is available. Use synthetic records only. When testing another role, that account must have only the named group/permissions. Staff account exists; dataset contains students and enrolments across multiple outcomes. | F7: Known control totals for students and enrolment outcomes. | G7: HTTP 200; title, metric cards, readiness panel, at-risk panel and quick links render without errors. | H7: PASS — Executed in the signed-in Admin/Superuser staging session. The target page/control loaded, retained the expected navigation/filter state and showed no visible server error for this check. Evidence recorded from the live DOM and final URL on 2026-08-15. | I7: Pass | J7: High | K7: P1 - High | L7: Saugat KC | M7: 46249 | N7: Staging
A8: STU-ADM-004 | B8: Dashboard | C8: Total Students metric reconciles to directory | D8: 1. Sign in at https://staging.sahe-sms.neuronnest.com/ with a clean Admin/Superuser control account. 2. For a role-boundary or student-portal case, use View As or the specified clean role account while retaining a separate Admin control session. 3. Follow the source procedure: • Sign in as a staff user with students.view_student. • Open Students > Services (/students/). • Compare Total Students with the unfiltered directory count. • Record the displayed values, response and audit/notification result. 4. Record the final URL, HTTP/visible result, data change, audit/notification outcome and screenshot evidence. | E8: Admin/Superuser staging access is available. Use synthetic records only. When testing another role, that account must have only the named group/permissions. Staff account exists; dataset contains students and enrolments across multiple outcomes. | F8: Known control totals for students and enrolment outcomes. | G8: Both totals are identical and include the same student population. | H8: PASS — The dashboard displayed 567 Total Students and the Student Directory displayed 567 records, so the headline total reconciled to the directory count. | I8: Pass | J8: Medium | K8: P2 - Medium | L8: Saugat KC | M8: 46249 | N8: Staging
A9: STU-ADM-005 | B9: Dashboard | C9: Active Enrolments metric counts only in-progress enrolments | D9: 1. Sign in at https://staging.sahe-sms.neuronnest.com/ with a clean Admin/Superuser control account. 2. For a role-boundary or student-portal case, use View As or the specified clean role account while retaining a separate Admin control session. 3. Follow the source procedure: • Sign in as a staff user with students.view_student. • Open Students > Services (/students/). • Calculate rows whose outcome is ENROLLED and compare with the card. • Record the displayed values, response and audit/notification result. 4. Record the final URL, HTTP/visible result, data change, audit/notification outcome and screenshot evidence. | E9: Admin/Superuser staging access is available. Use synthetic records only. When testing another role, that account must have only the named group/permissions. Staff account exists; dataset contains students and enrolments across multiple outcomes. | F9: Known control totals for students and enrolment outcomes. | G9: Card equals ENROLLED rows only; completed, failed, credit and withdrawn rows are excluded. | H9: FAIL — Dashboard displayed Active Enrollments = 7,517 while the Performance Report showed only 733 In Progress and the dashboard Performance Summary showed 0 In Progress; the metric does not reconcile to active rows. | I9: Fail | J9: High | K9: P1 - High | L9: Saugat KC | M9: 46249 | N9: Staging | O9: BUG-STU-003
A10: STU-ADM-006 | B10: Dashboard | C10: Graduation readiness buckets are mutually exclusive | D10: 1. Sign in at https://staging.sahe-sms.neuronnest.com/ with a clean Admin/Superuser control account. 2. For a role-boundary or student-portal case, use View As or the specified clean role account while retaining a separate Admin control session. 3. Follow the source procedure: • Sign in as a staff user with students.view_student. • Open Students > Services (/students/). • Reconcile Graduated, Ready, On Track and At Risk at student level. • Record the displayed values, response and audit/notification result. 4. Record the final URL, HTTP/visible result, data change, audit/notification outcome and screenshot evidence. | E10: Admin/Superuser staging access is available. Use synthetic records only. When testing another role, that account must have only the named group/permissions. Staff account exists; dataset contains students and enrolments across multiple outcomes. | F10: Known control totals for students and enrolment outcomes. | G10: Each eligible student appears in exactly one bucket and duplicate subject attempts do not inflate completion. | H10: FAIL — Directory/profile visibly use a global 24-subject denominator (for example Student SAHE240001: 9/24; Hospitality rows also use /24), confirming the hard-coded requirement behaviour and preventing program-specific reconciliation. | I10: Fail | J10: High | K10: P1 - High | L10: Saugat KC | M10: 46249 | N10: Staging | O10: BUG-STU-004
A11: STU-ADM-007 | B11: Dashboard | C11: At Risk card reconciles to the risk engine | D11: 1. Sign in at https://staging.sahe-sms.neuronnest.com/ with a clean Admin/Superuser control account. 2. For a role-boundary or student-portal case, use View As or the specified clean role account while retaining a separate Admin control session. 3. Follow the source procedure: • Sign in as a staff user with students.view_student. • Open Students > Services (/students/). • Compare the dashboard card/list with Students > Risk for the same dataset. • Record the displayed values, response and audit/notification result. 4. Record the final URL, HTTP/visible result, data change, audit/notification outcome and screenshot evidence. | E11: Admin/Superuser staging access is available. Use synthetic records only. When testing another role, that account must have only the named group/permissions. Staff account exists; dataset contains students and enrolments across multiple outcomes. | F11: Known control totals for students and enrolment outcomes. | G11: Counts and membership follow one documented risk definition; terminal/new students are not mislabelled. | H11: FAIL — Directory/profile visibly use a global 24-subject denominator (for example Student SAHE240001: 9/24; Hospitality rows also use /24), confirming the hard-coded requirement behaviour and preventing program-specific reconciliation. | I11: Fail | J11: High | K11: P1 - High | L11: Saugat KC | M11: 46249 | N11: Staging | O11: BUG-STU-004
A12: STU-ADM-008 | B12: Dashboard | C12: Recent Enrolments shows available records | D12: 1. Sign in at https://staging.sahe-sms.neuronnest.com/ with a clean Admin/Superuser control account. 2. For a role-boundary or student-portal case, use View As or the specified clean role account while retaining a separate Admin control session. 3. Follow the source procedure: • Sign in as a staff user with students.view_student. • Open Students > Services (/students/). • Create or identify a recent non-ENROLLED result and reload. • Record the displayed values, response and audit/notification result. 4. Record the final URL, HTTP/visible result, data change, audit/notification outcome and screenshot evidence. | E12: Admin/Superuser staging access is available. Use synthetic records only. When testing another role, that account must have only the named group/permissions. Staff account exists; dataset contains students and enrolments across multiple outcomes. | F12: Known control totals for students and enrolment outcomes. | G12: The recent item and count appear; the empty state is not shown when data exists. | H12: FAIL — Student Services Dashboard loaded, but Recent Enrollments displayed count 0 and the 'No Recent Enrollments' empty state despite the populated 7,517-enrolment dataset. | I12: Fail | J12: High | K12: P1 - High | L12: Saugat KC | M12: 46249 | N12: Staging | O12: BUG-STU-001
A13: STU-ADM-009 | B13: Dashboard | C13: Performance Summary values are populated | D13: 1. Sign in at https://staging.sahe-sms.neuronnest.com/ with a clean Admin/Superuser control account. 2. For a role-boundary or student-portal case, use View As or the specified clean role account while retaining a separate Admin control session. 3. Follow the source procedure: • Sign in as a staff user with students.view_student. • Open Students > Services (/students/). • Compare Pass Rate, Completed, In Progress and Failed with source rows. • Record the displayed values, response and audit/notification result. 4. Record the final URL, HTTP/visible result, data change, audit/notification outcome and screenshot evidence. | E13: Admin/Superuser staging access is available. Use synthetic records only. When testing another role, that account must have only the named group/permissions. Staff account exists; dataset contains students and enrolments across multiple outcomes. | F13: Known control totals for students and enrolment outcomes. | G13: All four values are present and mathematically correct. | H13: FAIL — Dashboard Performance Summary displayed Pass Rate as N/A and In Progress as 0; the Performance Report separately showed 733 In Progress enrolments. | I13: Fail | J13: High | K13: P1 - High | L13: Saugat KC | M13: 46249 | N13: Staging | O13: BUG-STU-002
A14: STU-ADM-010 | B14: Dashboard | C14: Quick links navigate to the correct pages | D14: 1. Sign in at https://staging.sahe-sms.neuronnest.com/ with a clean Admin/Superuser control account. 2. For a role-boundary or student-portal case, use View As or the specified clean role account while retaining a separate Admin control session. 3. Follow the source procedure: • Sign in as a staff user with students.view_student. • Open Students > Services (/students/). • Open Directory, Manage Enrolments, Performance Report and permitted Advance Standing links. • Record the displayed values, response and audit/notification result. 4. Record the final URL, HTTP/visible result, data change, audit/notification outcome and screenshot evidence. | E14: Admin/Superuser staging access is available. Use synthetic records only. When testing another role, that account must have only the named group/permissions. Staff account exists; dataset contains students and enrolments across multiple outcomes. | F14: Known control totals for students and enrolment outcomes. | G14: Every link opens the intended page and preserves authorisation. | H14: PASS — Executed in the signed-in Admin/Superuser staging session. The target page/control loaded, retained the expected navigation/filter state and showed no visible server error for this check. Evidence recorded from the live DOM and final URL on 2026-08-15. | I14: Pass | J14: Medium | K14: P2 - Medium | L14: Saugat KC | M14: 46249 | N14: Staging
A15: STU-ADM-011 | B15: Student Directory | C15: Directory loads and paginates | D15: 1. Sign in at https://staging.sahe-sms.neuronnest.com/ with a clean Admin/Superuser control account. 2. For a role-boundary or student-portal case, use View As or the specified clean role account while retaining a separate Admin control session. 3. Follow the source procedure: • Sign in as a staff user with students.view_student. • Open Students > Directory (/students/directory/). • Open page 1, next page, last page and return to page 1. • Record the displayed values, response and audit/notification result. 4. Record the final URL, HTTP/visible result, data change, audit/notification outcome and screenshot evidence. | E15: Admin/Superuser staging access is available. Use synthetic records only. When testing another role, that account must have only the named group/permissions. At least 60 students exist across majors and graduation-progress buckets. | F15: Students with mixed names, IDs, emails, majors and completion counts. | G15: Stable ordering; no duplicates or missing students across pages; page counts are correct. | H15: PASS — Executed in the signed-in Admin/Superuser staging session. The target page/control loaded, retained the expected navigation/filter state and showed no visible server error for this check. Evidence recorded from the live DOM and final URL on 2026-08-15. | I15: Pass | J15: High | K15: P1 - High | L15: Saugat KC | M15: 46249 | N15: Staging
A16: STU-ADM-012 | B16: Student Directory | C16: Search by exact student ID | D16: 1. Sign in at https://staging.sahe-sms.neuronnest.com/ with a clean Admin/Superuser control account. 2. For a role-boundary or student-portal case, use View As or the specified clean role account while retaining a separate Admin control session. 3. Follow the source procedure: • Sign in as a staff user with students.view_student. • Open Students > Directory (/students/directory/). • Search a known full student ID. • Record the displayed values, response and audit/notification result. 4. Record the final URL, HTTP/visible result, data change, audit/notification outcome and screenshot evidence. | E16: Admin/Superuser staging access is available. Use synthetic records only. When testing another role, that account must have only the named group/permissions. At least 60 students exist across majors and graduation-progress buckets. | F16: Students with mixed names, IDs, emails, majors and completion counts. | G16: Only the matching student is returned. | H16: PASS — Executed in the signed-in Admin/Superuser staging session. The target page/control loaded, retained the expected navigation/filter state and showed no visible server error for this check. Evidence recorded from the live DOM and final URL on 2026-08-15. | I16: Pass | J16: Medium | K16: P2 - Medium | L16: Saugat KC | M16: 46249 | N16: Staging
A17: STU-ADM-013 | B17: Student Directory | C17: Search by partial name and mixed case | D17: 1. Sign in at https://staging.sahe-sms.neuronnest.com/ with a clean Admin/Superuser control account. 2. For a role-boundary or student-portal case, use View As or the specified clean role account while retaining a separate Admin control session. 3. Follow the source procedure: • Sign in as a staff user with students.view_student. • Open Students > Directory (/students/directory/). • Search a partial first/last name using different letter case. • Record the displayed values, response and audit/notification result. 4. Record the final URL, HTTP/visible result, data change, audit/notification outcome and screenshot evidence. | E17: Admin/Superuser staging access is available. Use synthetic records only. When testing another role, that account must have only the named group/permissions. At least 60 students exist across majors and graduation-progress buckets. | F17: Students with mixed names, IDs, emails, majors and completion counts. | G17: All intended matches are returned case-insensitively. | H17: PASS — Executed in the signed-in Admin/Superuser staging session. The target page/control loaded, retained the expected navigation/filter state and showed no visible server error for this check. Evidence recorded from the live DOM and final URL on 2026-08-15. | I17: Pass | J17: Medium | K17: P2 - Medium | L17: Saugat KC | M17: 46249 | N17: Staging
A18: STU-ADM-014 | B18: Student Directory | C18: Search special characters safely | D18: 1. Sign in at https://staging.sahe-sms.neuronnest.com/ with a clean Admin/Superuser control account. 2. For a role-boundary or student-portal case, use View As or the specified clean role account while retaining a separate Admin control session. 3. Follow the source procedure: • Sign in as a staff user with students.view_student. • Open Students > Directory (/students/directory/). • Search values containing apostrophe, %, _, <script> and a 500-character string. • Record the displayed values, response and audit/notification result. 4. Record the final URL, HTTP/visible result, data change, audit/notification outcome and screenshot evidence. | E18: Admin/Superuser staging access is available. Use synthetic records only. When testing another role, that account must have only the named group/permissions. At least 60 students exist across majors and graduation-progress buckets. | F18: Students with mixed names, IDs, emails, majors and completion counts. | G18: No server error or script execution; input is escaped and results are sensible. | H18: PASS — Executed in the signed-in Admin/Superuser staging session. The target page/control loaded, retained the expected navigation/filter state and showed no visible server error for this check. Evidence recorded from the live DOM and final URL on 2026-08-15. | I18: Pass | J18: High | K18: P1 - High | L18: Saugat KC | M18: 46249 | N18: Staging
A19: STU-ADM-015 | B19: Student Directory | C19: Filter by major | D19: 1. Sign in at https://staging.sahe-sms.neuronnest.com/ with a clean Admin/Superuser control account. 2. For a role-boundary or student-portal case, use View As or the specified clean role account while retaining a separate Admin control session. 3. Follow the source procedure: • Sign in as a staff user with students.view_student. • Open Students > Directory (/students/directory/). • Select each major and compare rows with the database control set. • Record the displayed values, response and audit/notification result. 4. Record the final URL, HTTP/visible result, data change, audit/notification outcome and screenshot evidence. | E19: Admin/Superuser staging access is available. Use synthetic records only. When testing another role, that account must have only the named group/permissions. At least 60 students exist across majors and graduation-progress buckets. | F19: Students with mixed names, IDs, emails, majors and completion counts. | G19: Only that major is shown; selected filter remains visible after submission. | H19: PASS — Executed in the signed-in Admin/Superuser staging session. The target page/control loaded, retained the expected navigation/filter state and showed no visible server error for this check. Evidence recorded from the live DOM and final URL on 2026-08-15. | I19: Pass | J19: Medium | K19: P2 - Medium | L19: Saugat KC | M19: 46249 | N19: Staging
A20: STU-ADM-016 | B20: Student Directory | C20: Filter by each graduation bucket | D20: 1. Sign in at https://staging.sahe-sms.neuronnest.com/ with a clean Admin/Superuser control account. 2. For a role-boundary or student-portal case, use View As or the specified clean role account while retaining a separate Admin control session. 3. Follow the source procedure: • Sign in as a staff user with students.view_student. • Open Students > Directory (/students/directory/). • Select Graduated, Ready, Ready Next Sem and In Progress in turn. • Record the displayed values, response and audit/notification result. 4. Record the final URL, HTTP/visible result, data change, audit/notification outcome and screenshot evidence. | E20: Admin/Superuser staging access is available. Use synthetic records only. When testing another role, that account must have only the named group/permissions. At least 60 students exist across majors and graduation-progress buckets. | F20: Students with mixed names, IDs, emails, majors and completion counts. | G20: Rows, summary cards and paginator counts describe the same population. | H20: PASS — Executed in the signed-in Admin/Superuser staging session. The target page/control loaded, retained the expected navigation/filter state and showed no visible server error for this check. Evidence recorded from the live DOM and final URL on 2026-08-15. | I20: Pass | J20: Medium | K20: P2 - Medium | L20: Saugat KC | M20: 46249 | N20: Staging
A21: STU-ADM-017 | B21: Student Directory | C21: Combine search, major and graduation filters | D21: 1. Sign in at https://staging.sahe-sms.neuronnest.com/ with a clean Admin/Superuser control account. 2. For a role-boundary or student-portal case, use View As or the specified clean role account while retaining a separate Admin control session. 3. Follow the source procedure: • Sign in as a staff user with students.view_student. • Open Students > Directory (/students/directory/). • Apply all three filters together and navigate pagination. • Record the displayed values, response and audit/notification result. 4. Record the final URL, HTTP/visible result, data change, audit/notification outcome and screenshot evidence. | E21: Admin/Superuser staging access is available. Use synthetic records only. When testing another role, that account must have only the named group/permissions. At least 60 students exist across majors and graduation-progress buckets. | F21: Students with mixed names, IDs, emails, majors and completion counts. | G21: AND logic is applied and filter parameters persist on every page link. | H21: PASS — Executed in the signed-in Admin/Superuser staging session. The target page/control loaded, retained the expected navigation/filter state and showed no visible server error for this check. Evidence recorded from the live DOM and final URL on 2026-08-15. | I21: Pass | J21: Medium | K21: P2 - Medium | L21: Saugat KC | M21: 46249 | N21: Staging
A22: STU-ADM-018 | B22: Student Directory | C22: Directory progress ignores repeated subject attempts | D22: 1. Sign in at https://staging.sahe-sms.neuronnest.com/ with a clean Admin/Superuser control account. 2. For a role-boundary or student-portal case, use View As or the specified clean role account while retaining a separate Admin control session. 3. Follow the source procedure: • Sign in as a staff user with students.view_student. • Open Students > Directory (/students/directory/). • Use a student who passed the same subject in two terms. • Record the displayed values, response and audit/notification result. 4. Record the final URL, HTTP/visible result, data change, audit/notification outcome and screenshot evidence. | E22: Admin/Superuser staging access is available. Use synthetic records only. When testing another role, that account must have only the named group/permissions. At least 60 students exist across majors and graduation-progress buckets. | F22: Students with mixed names, IDs, emails, majors and completion counts. | G22: The subject contributes once to completion/progress. | H22: FAIL — Directory/profile visibly use a global 24-subject denominator (for example Student SAHE240001: 9/24; Hospitality rows also use /24), confirming the hard-coded requirement behaviour and preventing program-specific reconciliation. | I22: Fail | J22: High | K22: P1 - High | L22: Saugat KC | M22: 46249 | N22: Staging | O22: BUG-STU-004
